<?xml version="1.0"?>
<robot name="differential_drive_robot">
    <!-- Base Link -->
    <link name="base_link">
        <visual>
            <geometry>
                <box size="0.5 0.3 0.1"/> <!-- Chassis dimensions: length, width, height -->
            </geometry>
            <origin xyz="0 0 0.05" rpy="0 0 0"/> <!-- Position of the base link -->
            <material name="blue">
                <color rgba="0 0 1 1"/>
            </material>
        </visual>
    </link>

    <link name="lidar">
        <visual>
            <geometry>
                <cylinder radius="0.1" length="0.02"/> <!-- Lidar dimensions -->
            </geometry>
            <origin xyz="0 0 0" rpy="0 0 0"/> <!-- Position of the lidar -->
            <material name="green">
                <color rgba="0 1 0 1"/>
            </material>
        </visual>
    </link>

    <joint name="base_lidar" type="fixed">
        <parent link="base_link"/>
        <child link="lidar"/>
        <origin xyz="0 0 0.11" rpy="0 0 0"/> <!-- Position of lidar on the base -->
    </joint>

    <!-- Left Wheel -->
    <link name="left_wheel">
        <visual>
            <geometry>
                <cylinder radius="0.05" length="0.02"/> <!-- Wheel radius and thickness -->
            </geometry>
            <origin xyz="0 0 0" rpy="1.5708 0 0"/>
            <material name="black">
                <color rgba="0 0 0 1"/>
            </material>
        </visual>
    </link>

    <joint name="left_wheel_joint" type="continuous">
        <parent link="base_link"/>
        <child link="left_wheel"/>
        <origin xyz="-0.15 0.16 0" rpy="0 0 0"/> <!-- Position of left wheel -->
        <axis xyz="0 1 0"/>
    </joint>

    <link name="right_wheel">
        <visual>
            <geometry>
                <cylinder radius="0.05" length="0.02"/>
            </geometry>
            <origin xyz="0 0 0" rpy="-1.5708 0 0"/>
            <material name="black">
                <color rgba="0 0 0 1"/>
            </material>
        </visual>
    </link>
        <joint name="right_wheel_joint" type="continuous">
        <parent link= "base_link"/>
        <child link="right_wheel"/>
        <origin xyz="-0.15 -0.16 0" rpy="0 0 0"/> <!-- Position of right wheel -->
        <axis xyz="0 1 0"/>
    </joint>

    <!-- Caster Wheel -->
    <link name="caster_wheel">
        <visual>
            <geometry>
                <sphere radius="0.03"/> <!-- Caster wheel radius -->
            </geometry>
            <material name="gray">
                <color rgba="0.5 0.5 0.5 1"/>
            </material>
        </visual>
    </link>


    <joint name="caster_wheel_joint" type="continuous">
        <parent link="base_link"/>
        <child link="caster_wheel"/>
        <origin xyz="0.2 0 0" rpy="0 0 0"/> <!-- Position of caster wheel -->
        <axis xyz="1 1 1"/>
    </joint>
</robot>