<?xml version="1.0"?>
<robot name="simple robot">
  
<link name="base_link">
    <visual>
      <geometry>
        <cylinder length="0.1" radius="0.3"/>
      </geometry>
    <origin xyz="0 0 0" rpy="0 0 0"/>    
      <material name="green">
        <color rgba="0 1 0 1"/>
      </material>
    </visual>
</link>

<joint name="joint1" type="revolute">
    <parent link="base_link"/>
    <child link="link1"/>
    <origin xyz="0 0 0.05" rpy="0 0 0"/>
    <axis xyz="0 0 1"/>
    <limit effort="10" lower="-3.14" upper="3.14" velocity="1"/>
</joint>

<link name="link1">
    <visual>
        <geometry>
            <cylinder radius="0.08" length="0.5"/>
        </geometry>
        <origin xyz="0 0 0.25" rpy="0 0 0"/>
        <material name="yellow">
            <color rgba="0 1 0 1"/>
        </material>
    </visual>
</link>

<joint name="joint2" type="prismatic">
    <parent link="link1"/>
    <child link="link2"/>
    <origin xyz="0 0 0.5" rpy="0 0 0"/>
    <axis xyz="0 1 0"/>
    <limit effort="10" lower="-3.14" upper="3.14" velocity="1"/>
</joint>

<link name="link2">
    <visual>
        <geometry>
            <box size="0.2 0.7 0.1"/>
        </geometry>
        <origin xyz="0 0 0.05" rpy="0 0 0"/>
        <material name="blue">
            <color rgba="0 0 1 1"/>
        </material>
    </visual>
</link>

</robot>