<?xml version="1.0"?>
<robot name="differential drive robot" xmlns:xacro="http://www.ros.org/wiki/xacro">
  
<!-- Define the value of pi -->
<xacro:property name="pi_const" value="3.14159"/>  

<!-- Body parameters -->
<xacro:property name="a" value="1"/>
<xacro:property name="b" value="0.3"/>
<xacro:property name="c" value="0.6"/>
<xacro:property name="r" value="0.15"/>
<xacro:property name="d" value="0.1"/>

  <xacro:property name="s1" value="${b/2+r}"/>
  <xacro:property name="s2" value="${2*r}"/>
  <xacro:property name="s3" value="${2*r}"/>
  <xacro:property name="s4" value="${c/2+d/2}"/>


<!-- densities -->
<xacro:property name="d1" value="2710.0"/>
<xacro:property name="d2" value="2710.0"/>
<xacro:property name="d3" value="2710.0"/>

<!-- mass -->
<xacro:property name="m1" value="${d1*a*b*c}"/>
<xacro:property name="m2" value="${d2*pi_const*r*r*d}"/>
<xacro:property name="m3" value="${d3*(4.0/3.0)*pi_const*r*r*r}"/>

<xacro:property name="Ix_body" value="${(1/12.0)*m1*(b*b+c*c)}"/>
<xacro:property name="Iy_body" value="${(1/12.0)*m1*(b*b+a*a)}"/>
<xacro:property name="Iz_body" value="${(1/12.0)*m1*(a*a+c*c)}"/>

<xacro:property name="Iz_wheel" value="${0.5*m2*r*r}"/>
<xacro:property name="I_wheel" value="${(1/12.0)*m2*(3.0*r*r+d*d)}"/>

<xacro:property name="I_caster" value="${(2.0/5.0)*m3*r*r}"/>

<xacro:macro name="inertia_body">
    <inertial>
    <origin xyz="0 0 ${s1}" rpy="0 0 0"/>
        <mass value="${m1}"/>
        <inertia ixx="${Ix_body}" ixy="0" ixz="0" iyy="${Iy_body}" iyz="0" izz="${Iz_body}"/>
    </inertial>
</xacro:macro>

<xacro:macro name="inertia_wheel">
    <inertial>
        <origin xyz="0 0 0" rpy="1.5787 0 0"/>
        <mass value="${m2}"/>
        <inertia ixx="${I_wheel}" ixy="0" ixz="0" iyy="${I_wheel}" iyz="0" izz="${Iz_wheel}"/>
    </inertial>
</xacro:macro>

<xacro:macro name="inertia_caster">
    <inertial>
        <origin xyz="0 0 0" rpy="0 0 0"/>
        <mass value="${m3}"/>
        <inertia ixx="${I_caster}" ixy="0" ixz="0" iyy="${I_caster}" iyz="0" izz="${I_caster}"/>
    </inertial> 
</xacro:macro>

<xacro:include filename="$(find gazeboRobot)/model/model.gazebo"/>

<link name="base_footprint"></link>

<joint name="body_link_joint" type="fixed"> 
    <parent link="base_footprint"/>
    <child link="body_link"/>
</joint>

<link name="body_link">
    <visual>
        <geometry>
            <box size="${a} ${c} ${b}"/>
        </geometry>
        <origin xyz="0 0 ${s1}" rpy="0 0 0"/>
    </visual>
    <collision>
        <geometry>
            <box size="${a} ${c} ${b}"/>
        </geometry>
        <origin xyz="0 0 ${s1}" rpy="0 0 0"/>
    </collision>
    <xacro:inertia_body/>
</link>

<joint name="wheel_right_joint" type="continuous">
    <parent link="body_link"/>
    <child link="wheel_right"/>
    <origin xyz="${-s2} ${-s4} ${r}" rpy="0 0 0"/>
    <axis xyz="0 1 0"/>
    <limits effort="50000" velocity="10"/>
    <dynamics damping="0.5" friction="0.5"/>
</joint>

<link name="wheel_right">
    <visual>
        <geometry>
            <cylinder radius="${r}" length="${d}"/>
        </geometry>
        <origin xyz="0 0 0" rpy="1.5787 0 0"/>
    </visual>
    <collision>
        <geometry>
            <cylinder radius="${r}" length="${d}"/>
        </geometry>
       </collision>
    <xacro:inertia_wheel/>
</link>

<joint name="wheel_left_joint" type="continuous">
    <parent link="body_link"/>
    <child link="wheel_left"/>
    <origin xyz="${-s2} ${s4} ${r}" rpy="0 0 0"/>
    <axis xyz="0 1 0"/>
    <limits effort="50000" velocity="10"/>
    <dynamics damping="0.5" friction="0.5"/>
</joint>

<link name="wheel_left">
    <visual>
        <geometry>
            <cylinder radius="${r}" length="${d}"/>
        </geometry>
        <origin xyz="0 0 0" rpy="1.5787 0 0"/>
    </visual>
    <collision>
        <geometry>
            <cylinder radius="${r}" length="${d}"/>
        </geometry>
       </collision>
    <xacro:inertia_wheel/>
</link>

<joint name="caster_joint" type="continuous">
    <parent link="body_link"/>
    <child link="caster"/>
    <origin xyz="${s3} 0 ${r}" rpy="0 0 0"/>
    <axis xyz="1 1 1"/>
    <dynamics damping="0.5" friction="0.0005"/>
</joint>

<link name="caster">
    <visual>
        <geometry>
            <sphere radius="${r}"/>
        </geometry>
        <origin xyz="0 0 0" rpy="0 0 0"/>
    </visual>
    <collision>
        <geometry>
            <sphere radius="${r}"/>
        </geometry>
    </collision>
    <xacro:inertia_caster/>
</link>

</robot>